<?xml version="1.0"?>
<robot xmlns:xacro="http://www.ros.org/wiki/xacro" name="r2d2">
    
    <!-- 
        R2-D2 Main Body
        
        Includes:
        - Head
        - Torso
        - Camera
    -->
    
    <xacro:macro name="body">

        <!-- Head -->
        <link name="top_body">
            <inertial>
                <origin xyz="0.0 0.0 0.0" rpy="0.0 0.0 0.0"/>
                <mass value="20.0"/>
                <xacro:solid_sphere_inertia m="20" r="1.5"/>
            </inertial>
            <visual name="top_body_visual">
                <origin xyz="0.0 0.0 0.0" rpy="0.0 0.0 0.0"/>
                <geometry>
                    <sphere radius="1.5"/>
                </geometry>
                <material name="silver"/>
            </visual>
            <collision name='top_body_collision'>
                <origin xyz="0.0 0.0 0.0" rpy="0.0 0.0 0.0"/>
                <geometry>
                    <sphere radius="1.5"/>
                </geometry>
            </collision>
        </link>

        <!-- Torso -->
        <link name="bottom_body">
            <pose>0 0 0 0 0 0</pose>
            <inertial>
                <origin xyz="0.0 0.0 0.0" rpy="0.0 0.0 0.0"/>
                <mass value="30.0"/>
                <xacro:solid_cylinder_inertia m="30" h="3.0" r="1.5"/>
            </inertial>
            <visual name="bottom_body_visual">
                <origin xyz="0.0 0.0 0.0" rpy="0.0 0.0 0.0"/>
                <geometry>
                    <cylinder radius="1.5" length="3.0"/>
                </geometry>
                <material name="silver"/>
            </visual>
            <collision name='bottom_body_collision'>
                <origin xyz="0.0 0.0 0.0" rpy="0.0 0.0 0.0"/>
                <geometry>
                    <cylinder radius="1.5" length="3.0"/>
                </geometry>
            </collision>
        </link>

        <!-- Camera -->
        <link name="camera_housing">
            <inertial>
                <origin xyz="0.0 0.0 0.0" rpy="0.0 0.0 0.0"/>
                <mass value="1.0"/>
                <inertia ixx="0.0" ixy="0.0" ixz="0.0" iyy="0.0" iyz="0.0" izz="0.0"/>
            </inertial>
            <visual name="">
                <origin xyz="0.0 0.0 0.0" rpy="0.0 0.0 0.0"/>
                <geometry>
                    <box size="0.5 0.4 0.5"/>
                </geometry>
                <material name="blue" />
            </visual>
            <collision>
                <origin xyz="0.0 0.0 0.0" rpy="0.0 0.0 0.0"/>
                <geometry>
                    <box size="0.5 0.2 0.5"/>
                </geometry>
            </collision>
        </link>

        <link name="camera_optical_frame">
            <inertial>
                <origin xyz="0.0 0.0 0.0" rpy="0.0 0.0 0.0"/>
                <mass value="1.0"/>
                <inertia ixx="0.0" ixy="0.0" ixz="0.0" iyy="0.0" iyz="0.0" izz="0.0"/>
            </inertial>
            <visual name="">
                <origin xyz="0.0 0.0 0.0" rpy="0.0 0.0 0.0"/>
                <geometry>
                    <sphere radius="0.15"/>
                </geometry>
                <material name="black"/>
            </visual>
            <collision>
                <origin xyz="0.0 0.0 0.0" rpy="0.0 0.0 0.0"/>
                <geometry>
                    <sphere radius="0.15"/>
                </geometry>
            </collision>
        </link>

        <joint name="head_joint" type="revolute">
            <parent link="bottom_body"/>
            <child link="top_body"/>
            <origin xyz="0.0 0.0 1.5" rpy="0.0 0.0 0.0"/>
            <limit lower="-1.0" upper="1.0" effort="0.0" velocity="1.0"/>
        </joint>

        <joint name="base_joint" type="fixed">
            <parent link="base_unit"/>
            <child link="bottom_body"/>
            <origin xyz="0.0 0.0 2.5" rpy="0.0 0.0 0.0"/>
        </joint>

        <joint name="camera_housing_joint" type="fixed">
            <origin xyz="0.0 1.25 0.6" rpy="0.0 0.0 0.0"/>
            <parent link="top_body"/>
            <child link="camera_housing"/>
            <axis xyz="0.0 0.0 0.0"/>
        </joint>

        <joint name="camera_optical_joint" type="fixed">
            <origin xyz="0.0 0.15 0.0" rpy="0.0 0.0 0.0"/>
            <parent link="camera_housing"/>
            <child link="camera_optical_frame"/>
            <axis xyz="0.0 0.0 0.0"/>
        </joint>

    </xacro:macro>

</robot>